.\" DO NOT MODIFY THIS FILE!  It was generated by help2man 1.46.4.
.TH EIGER-MASK "1" "July 2015" "PyFAI" "User Commands"
.SH NAME
eiger-mask \- eiger-mask
.SH DESCRIPTION
.SS "Traceback (most recent call last):"
.IP
File "scripts/eiger\-mask", line 68, in <module>
.IP
mask = extract_mask(infile)
.IP
File "scripts/eiger\-mask", line 55, in extract_mask
.IP
h = h5py.File(infile, "r")
.IP
File "/usr/lib/python2.7/dist\-packages/h5py/_hl/files.py", line 231, in __init__
.IP
fid = make_fid(name, mode, userblock_size, fapl)
.IP
File "/usr/lib/python2.7/dist\-packages/h5py/_hl/files.py", line 78, in make_fid
.IP
fid = h5f.open(name, h5f.ACC_RDONLY, fapl=fapl)
.IP
File "_objects.pyx", line 54, in h5py._objects.with_phil.wrapper (\fI\,/home/jerome/debian7/h5py\-2.4.0/h5py/_objects\/\fP.c:2346)
File "_objects.pyx", line 55, in h5py._objects.with_phil.wrapper (\fI\,/home/jerome/debian7/h5py\-2.4.0/h5py/_objects\/\fP.c:2285)
File "h5f.pyx", line 72, in h5py.h5f.open (\fI\,/home/jerome/debian7/h5py\-2.4.0/h5py/h5f\/\fP.c:1775)
.PP
IOError: Unable to open file (Unable to open file: name = '/users/kieffer/workspace\-400/pyfai/\-\-help', errno = 2, error message = 'no such file or directory', flags = 0, o_flags = 0)
